Workbook

Sheet Hoja2
A1: ESTADO
A2: ASISTIRA
A3: APAGADO
A4: NO PODRA ASISTIR
A5: NO LLAMAR
A6: VOLVER A LLAMAR
A7: NO CONTESTA
A8: ENVIAR AL CORREO
A9: NO PUEDE CONFIRMAR
A10: FUERA DE SERVICIO
A11: EQUIVOCADO

Sheet Hoja3
A1: BOCAS DEL TORO | C1: MULTI VENTAS IDALIDES | E1: 64728992
A2: BOCAS DEL TORO | C2: CAFETERIA YAMI | E2: 65467904
A3: BOCAS DEL TORO | C3: KIOSKO YARIALYS | E3: 65867202
A4: BOCAS DEL TORO | C4: FONDA BOLICIN | E4: 62494147
A5: BOCAS DEL TORO | C5: FONDA CARMELA | E5: 64217218
A6: BOCAS DEL TORO | C6: FLORISTERIA LA PRIMAVERA | E6: 64284378
A7: BOCAS DEL TORO | C7: FRUTAS Y DESECHABLES CHIRIQUI | E7: 7756849
A8: BOCAS DEL TORO | C8: ABARROTERIA LA SOFI | E8: 66221649
A9: BOCAS DEL TORO | C9: ABARROTERIA SABINA 2 | E9: 64002910
A10: BOCAS DEL TORO | C10: ABARROTERIA AVILA | E10: 67347086
A11: BOCAS DEL TORO | C11: ABARROTERIA JP STORE | E11: 67890276
A12: BOCAS DEL TORO | C12: ABARROTERIA DON FRANCO | E12: 69463180
... A221: BOCAS DEL TORO | C221: TALLER HITO | E221: 66524250
A222: BOCAS DEL TORO | C222: TALLER MANUEL
A223: BOCAS DEL TORO | C223: TALLER BIRMIGHAM | E223: 66572910
A224: BOCAS DEL TORO | C224: TALLER DE MECANICA Y CHAPISTERIA SILVERA | E224: 68357511
A225: BOCAS DEL TORO | C225: TALLER ESPINOZA | E225: 62063623
A226: BOCAS DEL TORO | C226: TALLER ORTIZ N°1 | E226: 64145702
A227: BOCAS DEL TORO | C227: TALLER JORGITO | E227: 63183961
A228: BOCAS DEL TORO | C228: TALLER RAUL CASTRO | E228: 69202504
A229: BOCAS DEL TORO | C229: TALLER MENENGO ( LA GOTERA) | E229: 66779673
A230: BOCAS DEL TORO | C230: VETERINARIA SAN JOSE | E230: 60902503
A231: BOCAS DEL TORO | C231: AGROVETERINARIA LA VÍA RURAL | E231: 7094131
A232: BOCAS DEL TORO | C232: ROPA AMERICANA Y & R | E232: 63282947
A233: BOCAS DEL TORO | C233: MI LIBRERIA INTERNET | E233: 7746704
A234: BOCAS DEL TORO | C234: VIDRIOS Y VENTANAS CASERE | E234: 7301156
... A278: COCLE | C278: DISFRUTAS CH | E278: 66717720
A279: COCLE | C279: ABARROTERIA BIANCA
A280: COCLE | C280: ABARROTERIA METRO 15 | E280: 66448184
A281: COCLE | C281: ABARROTERIA TITO | E281: 65126194
A282: COCLE | C282: ABARROTERIA RICKY | E282: 66617517
A283: COCLE | C283: ABARROTERIA LOS PINOS VOLCAN | E283: 66609222
A284: COCLE | C284: COPIAS & IMPRESIONES LUVY | E284: 68564059
A285: COCLE | C285: RESTAURANTE LIANG | E285: 7751306
A286: COCLE | C286: FABRICA AGRO INDUST DE HELAD Y PAL JAQUE | E286: 7303199
A287: COCLE | C287: LEGUMBRES Y FRUTAS DONDE EDUARDO G | E287: 67019047
A288: COCLE | C288: MARISEL SALON | E288: 66476191
A289: COCLE | C289: FONDA LA ESKINA | E289: 65020773
A290: COCLE | C290: FONDA DOÑA EIRA | E290: 68931466
A291: COCLE | C291: LAVAMATICO DOÑA EVIDELIA | E291: 68640875
...

Sheet RESULTADO 
A1: =Hoja2!A2 -> ASISTIRA | B1: =COUNTIF(Tabla1[ESTADO],'RESULTADO '!A1) -> 1122
A2: =Hoja2!A3 -> APAGADO | B2: =COUNTIF(Tabla1[ESTADO],'RESULTADO '!A2) -> 671
A3: =Hoja2!A4 -> NO PODRA ASISTIR | B3: =COUNTIF(Tabla1[ESTADO],'RESULTADO '!A3) -> 409
A4: =Hoja2!A5 -> NO LLAMAR | B4: =COUNTIF(Tabla1[ESTADO],'RESULTADO '!A4) -> 173
A5: =Hoja2!A6 -> VOLVER A LLAMAR | B5: =COUNTIF(Tabla1[ESTADO],'RESULTADO '!A5) -> 34
A6: =Hoja2!A7 -> NO CONTESTA | B6: =COUNTIF(Tabla1[ESTADO],'RESULTADO '!A6) -> 887
A7: =Hoja2!A8 -> ENVIAR AL CORREO | B7: =COUNTIF(Tabla1[ESTADO],'RESULTADO '!A7) -> 17
A8: =Hoja2!A9 -> NO PUEDE CONFIRMAR | B8: =COUNTIF(Tabla1[ESTADO],'RESULTADO '!A8) -> 133
A9: =Hoja2!A10 -> FUERA DE SERVICIO | B9: =COUNTIF(Tabla1[ESTADO],'RESULTADO '!A9) -> 396
A10: LLAMADAS FALTANTES | B10: =COUNTBLANK(Tabla1[ESTADO]) -> 74
A11: LLAMADAS HECHAS | B11: =SUM(B1:B9) -> 3842
B13: hechas | C13: asignadas | D13: por llamar
A14: BOCAS DEL TORO | B14: =IF(IF(COUNTIFS(Tabla1[REGIONAL],'RESULTADO '!A14,Tabla1[ESTADO],"<>")=0,"",COUNTIFS(Tabla1[REGIONAL],'RESULTADO '!A14,Tabla1[ESTADO],"<>"))=C14,"✅",COUNTIFS(Tabla1[REGIONAL],'RESULTADO '!A14,Tabla1[ESTADO],"<>")) -> 317 | C14: =COUNTIF(Tabla1[REGIONAL],'RESULTADO '!A14:A25) -> 322 | D14: =IFERROR(C14-B14,0) -> 5 | E14: =IF(D14=0,"✅",D14) -> 5
A15: COCLE | B15: =IF(IF(COUNTIFS(Tabla1[REGIONAL],'RESULTADO '!A15,Tabla1[ESTADO],"<>")=0,"",COUNTIFS(Tabla1[REGIONAL],'RESULTADO '!A15,Tabla1[ESTADO],"<>"))=C15,"✅",COUNTIFS(Tabla1[REGIONAL],'RESULTADO '!A15,Tabla1[ESTADO],"<>")) -> ✅ | C15: =COUNTIF(Tabla1[REGIONAL],'RESULTADO '!A15:A26) -> 266 | D15: =IFERROR(C15-B15,0) -> 0 | E15: =IF(D15=0,"✅",D15) -> ✅
A16: COLON | B16: =IF(IF(COUNTIFS(Tabla1[REGIONAL],'RESULTADO '!A16,Tabla1[ESTADO],"<>")=0,"",COUNTIFS(Tabla1[REGIONAL],'RESULTADO '!A16,Tabla1[ESTADO],"<>"))=C16,"✅",COUNTIFS(Tabla1[REGIONAL],'RESULTADO '!A16,Tabla1[ESTADO],"<>")) -> 171 | C16: =COUNTIF(Tabla1[REGIONAL],'RESULTADO '!A16:A26) -> 183 | D16: =IFERROR(C16-B16,0) -> 12 | E16: =IF(D16=0,"✅",D16) -> 12
A17: DARIEN | B17: =IF(IF(COUNTIFS(Tabla1[REGIONAL],'RESULTADO '!A17,Tabla1[ESTADO],"<>")=0,"",COUNTIFS(Tabla1[REGIONAL],'RESULTADO '!A17,Tabla1[ESTADO],"<>"))=C17,"✅",COUNTIFS(Tabla1[REGIONAL],'RESULTADO '!A17,Tabla1[ESTADO],"<>")) -> ✅ | C17: =COUNTIF(Tabla1[REGIONAL],'RESULTADO '!A17:A26) -> 176 | D17: =IFERROR(C17-B17,0) -> 0 | E17: =IF(D17=0,"✅",D17) -> ✅
A18: DAVID | B18: =IF(IF(COUNTIFS(Tabla1[REGIONAL],'RESULTADO '!A18,Tabla1[ESTADO],"<>")=0,"",COUNTIFS(Tabla1[REGIONAL],'RESULTADO '!A18,Tabla1[ESTADO],"<>"))=C18,"✅",COUNTIFS(Tabla1[REGIONAL],'RESULTADO '!A18,Tabla1[ESTADO],"<>")) -> ✅ | C18: =COUNTIF(Tabla1[REGIONAL],'RESULTADO '!A18:A27) -> 357 | D18: =IFERROR(C18-B18,0) -> 0 | E18: =IF(D18=0,"✅",D18) -> ✅
A19: GUNA YALA | B19: =IF(IF(COUNTIFS(Tabla1[REGIONAL],'RESULTADO '!A19,Tabla1[ESTADO],"<>")=0,"",COUNTIFS(Tabla1[REGIONAL],'RESULTADO '!A19,Tabla1[ESTADO],"<>"))=C19,"✅",COUNTIFS(Tabla1[REGIONAL],'RESULTADO '!A19,Tabla1[ESTADO],"<>")) -> ✅ | C19: =COUNTIF(Tabla1[REGIONAL],'RESULTADO '!A19:A28) -> 213 | D19: =IFERROR(C19-B19,0) -> 0 | E19: =IF(D19=0,"✅",D19) -> ✅
A20: HERRERA | B20: =IF(IF(COUNTIFS(Tabla1[REGIONAL],'RESULTADO '!A20,Tabla1[ESTADO],"<>")=0,"",COUNTIFS(Tabla1[REGIONAL],'RESULTADO '!A20,Tabla1[ESTADO],"<>"))=C20,"✅",COUNTIFS(Tabla1[REGIONAL],'RESULTADO '!A20,Tabla1[ESTADO],"<>")) -> 571 | C20: =COUNTIF(Tabla1[REGIONAL],'RESULTADO '!A20:A29) -> 627 | D20: =IFERROR(C20-B20,0) -> 56 | E20: =IF(D20=0,"✅",D20) -> 56 | G20: FERIA DE FINANCIAMIENTO
A21: LOS SANTOS | B21: =IF(IF(COUNTIFS(Tabla1[REGIONAL],'RESULTADO '!A21,Tabla1[ESTADO],"<>")=0,"",COUNTIFS(Tabla1[REGIONAL],'RESULTADO '!A21,Tabla1[ESTADO],"<>"))=C21,"✅",COUNTIFS(Tabla1[REGIONAL],'RESULTADO '!A21,Tabla1[ESTADO],"<>")) -> ✅ | C21: =COUNTIF(Tabla1[REGIONAL],'RESULTADO '!A21:A30) -> 266 | D21: =IFERROR(C21-B21,0) -> 0 | E21: =IF(D21=0,"✅",D21) -> ✅ | I21: =NOW() -> 46090.609
A22: PANAMA ESTE | B22: =IF(IF(COUNTIFS(Tabla1[REGIONAL],'RESULTADO '!A22,Tabla1[ESTADO],"<>")=0,"",COUNTIFS(Tabla1[REGIONAL],'RESULTADO '!A22,Tabla1[ESTADO],"<>"))=C22,"✅",COUNTIFS(Tabla1[REGIONAL],'RESULTADO '!A22,Tabla1[ESTADO],"<>")) -> ✅ | C22: =COUNTIF(Tabla1[REGIONAL],'RESULTADO '!A22:A31) -> 267 | D22: =IFERROR(C22-B22,0) -> 0 | E22: =IF(D22=0,"✅",D22) -> ✅ | I22: LLAMADAS POR REALIZAR | K22: =COUNTA(Tabla1[TELEFONO]) -> 3911
A23: PANAMA OESTE | B23: =IF(IF(COUNTIFS(Tabla1[REGIONAL],'RESULTADO '!A23,Tabla1[ESTADO],"<>")=0,"",COUNTIFS(Tabla1[REGIONAL],'RESULTADO '!A23,Tabla1[ESTADO],"<>"))=C23,"✅",COUNTIFS(Tabla1[REGIONAL],'RESULTADO '!A23,Tabla1[ESTADO],"<>")) -> 499 | C23: =COUNTIF(Tabla1[REGIONAL],'RESULTADO '!A23:A33) -> 500 | D23: =IFERROR(C23-B23,0) -> 1 | E23: =IF(D23=0,"✅",D23) -> 1 | I23: =A11 -> LLAMADAS HECHAS | K23: =B11 -> 3842
A24: SAN MIGUELITO | B24: =IF(IF(COUNTIFS(Tabla1[REGIONAL],'RESULTADO '!A24,Tabla1[ESTADO],"<>")=0,"",COUNTIFS(Tabla1[REGIONAL],'RESULTADO '!A24,Tabla1[ESTADO],"<>"))=C24,"✅",COUNTIFS(Tabla1[REGIONAL],'RESULTADO '!A24,Tabla1[ESTADO],"<>")) -> ✅ | C24: =COUNTIF(Tabla1[REGIONAL],'RESULTADO '!A24:A34) -> 203 | D24: =IFERROR(C24-B24,0) -> 0 | E24: =IF(D24=0,"✅",D24) -> ✅
A25: VERAGUAS | B25: =IF(IF(COUNTIFS(Tabla1[REGIONAL],'RESULTADO '!A25,Tabla1[ESTADO],"<>")=0,"",COUNTIFS(Tabla1[REGIONAL],'RESULTADO '!A25,Tabla1[ESTADO],"<>"))=C25,"✅",COUNTIFS(Tabla1[REGIONAL],'RESULTADO '!A25,Tabla1[ESTADO],"<>")) -> ✅ | C25: =COUNTIF(Tabla1[REGIONAL],'RESULTADO '!A25:A35) -> 536 | D25: =IFERROR(C25-B25,0) -> 0 | E25: =IF(D25=0,"✅",D25) -> ✅ | I25: =A1 -> ASISTIRA | J25: =A3 -> NO PODRA ASISTIR | K25: =A4 -> NO LLAMAR
B26: =IF(IF(COUNTIFS(Tabla1[REGIONAL],'RESULTADO '!A26,Tabla1[ESTADO],"<>")=0,"",COUNTIFS(Tabla1[REGIONAL],'RESULTADO '!A26,Tabla1[ESTADO],"<>")),"✅",B26) -> #VALUE! | I26: =B1 -> 1122 | J26: =B3 -> 409 | K26: =B4 -> 173
I27: =A10 -> LLAMADAS FALTANTES | J27: =A5 -> VOLVER A LLAMAR | K27: =A6 -> NO CONTESTA
I28: =B10 -> 74 | J28: =B5 -> 34 | K28: =B6 -> 887
I29: =A2 -> APAGADO | J29: =A7 -> ENVIAR AL CORREO | K29: =A8 -> NO PUEDE CONFIRMAR
I30: =B2 -> 671 | J30: =B7 -> 17 | K30: =B8 -> 133
I31: FUERA DE SERVICIO
I32: =B9 -> 396
G33: SE HA REALIZADO EL | J33: =B11/K22 -> 0.98235745 | K33: DE LAS LLAMADAS

Sheet BASE DE DASTO 
B1: ="☎️ "&'RESULTADO '!I22&" "&'RESULTADO '!K22 -> ☎️ LLAMADAS POR REALIZAR 3911 | E1: ="📞"&'RESULTADO '!A11&" "&'RESULTADO '!B11 -> 📞 LLAMADAS HECHAS 3842 | H1: ="⚠️ "&'RESULTADO '!A10&" "&'RESULTADO '!B10 -> ⚠️ LLAMADAS FALTANTES 74 | K1: =IFERROR('RESULTADO '!J33,0) -> 0.98235745 | L1: DE LLAMADAS REALIZAS
A2: ="✔️ "&'RESULTADO '!A1&" "&'RESULTADO '!B1 -> ✔️ ASISTIRA 1122 | B2: ="📵 "&'RESULTADO '!A2&" "&'RESULTADO '!B2 -> 📵 APAGADO 671 | C2: ="❌"&'RESULTADO '!A3&" "&'RESULTADO '!B3 -> ❌NO PODRA ASISTIR 409 | D2: ="🔄 "&'RESULTADO '!A5&" "&'RESULTADO '!B5 -> 🔄 VOLVER A LLAMAR 34 | E2: ="🚫 "&'RESULTADO '!A4&" "&'RESULTADO '!B4 -> 🚫 NO LLAMAR 173 | F2: ="❓"&'RESULTADO '!A8&" "&'RESULTADO '!B8 -> ❓NO PUEDE CONFIRMAR 133 | G2: ="📧 "&'RESULTADO '!A7&" "&'RESULTADO '!B7 -> 📧 ENVIAR AL CORREO 17 | H2: ="📴 "&'RESULTADO '!A6&" "&'RESULTADO '!B6 -> 📴 NO CONTESTA 887 | I2: =" 📴 "&'RESULTADO '!A9&" "&'RESULTADO '!B9 -> 📴 FUERA DE SERVICIO 396
A3: =IFERROR("LLAMADAS A REALIZAR POR REGIONAL: "&'RESULTADO '!A14&" "&'RESULTADO '!E14&" | "&'RESULTADO '!A15&" "&'RESULTADO '!E15&" | "&'RESULTADO '!A16&" "&'RESULTADO '!E16&" | "&'RESULTADO '!A17&" "&'RESULTADO '!E17&" | "&'RESULTADO '!A18&" "&'RESULTADO '!E18&" | "&'RESULTADO '!A19&" "&'RESULTADO '!E19&" | "&'RESULTADO '!A20&" "&'RESULTADO '!E20&" | "&'RESULTADO '!A21&" "&'RESULTADO '!E21&" | "&'RESULTADO '!A22&" "&'RESULTADO '!E22&" | "&'RESULTADO '!A23&" "&'RESULTADO '!E23&" | "&'RESULTADO '!A24&" "&'RESULTADO '!E24&" | "&'RESULTADO '!A25&" "&'RESULTADO '!E25,"") -> LLAMADAS A REALIZAR POR REGIONAL: BOCAS DEL TORO 5 | COCLE ✅ | COLON 12 | DARIEN ✅ | DAVID ✅ | GUNA YALA ✅ | HERRERA 56 | LOS SANTOS ✅ | PANAMA ESTE ✅ | PANAMA OESTE 1 | SAN MIGUELITO ✅ | VERAGUAS ✅
A4: REGIONAL | B4: COLABORADOR | C4: NOMBRE DE LA EMPRESA | D4: NOM. EMPRENDEDOR | E4: TELEFONO | F4: CORREO | G4: ESTADO | H4: LLAMADA 1 | I4: HORA | J4: LLAMADA 2 | K4: HORA2 | L4: OBSERVACION
A5: BOCAS DEL TORO | B5: Felix de leon | C5: ebanisteria | E5: 67793529 | G5: NO PODRA ASISTIR | H5: 46084 | I5: 0.54722222 | L5: persona me indico que ahora reside en veraguas y que cuando se realice una feria en veraguas se le avise
A6: BOCAS DEL TORO | B6: Felix de leon | C6: MULTI VENTAS IDALIDES | E6: 64728992 | G6: NO CONTESTA | H6: 46084 | I6: 0.55486111
A7: BOCAS DEL TORO | B7: Felix de leon | C7: CAFETERIA YAMI | D7: xiomara atencio | E7: 65467904 | G7: ASISTIRA | H7: 46084 | I7: 0.55486111
A8: BOCAS DEL TORO | B8: Felix de leon | C8: KIOSKO YARIALYS | E8: 65867202 | G8: NO CONTESTA | H8: 46084 | I8: 0.55555556
A9: BOCAS DEL TORO | B9: Felix de leon | C9: FONDA BOLICIN | E9: 62494147 | G9: NO CONTESTA | H9: 46084 | I9: 0.55694444
A10: BOCAS DEL TORO | B10: Felix de leon | C10: FONDA CARMELA | E10: 64217218 | G10: NO CONTESTA | H10: 46084 | I10: 0.56041667
A11: BOCAS DEL TORO | B11: Felix de leon | C11: FLORISTERIA LA PRIMAVERA | E11: 64284378 | G11: ASISTIRA | H11: 46084 | I11: 0.5625
A12: BOCAS DEL TORO | B12: Felix de leon | C12: FRUTAS Y DESECHABLES CHIRIQUI | E12: 7756849 | G12: NO PODRA ASISTIR | H12: 46084 | I12: 0.56388889
A13: BOCAS DEL TORO | B13: Felix de leon | C13: ABARROTERIA LA SOFI | D13: maria flora troya | E13: 66221649 | G13: ASISTIRA | H13: 46084 | I13: 0.56666667
A14: BOCAS DEL TORO | B14: Felix de leon | C14: ABARROTERIA SABINA 2 | E14: 64002910 | G14: APAGADO | H14: 46084 | I14: 0.56805556
A15: BOCAS DEL TORO | B15: Felix de leon | C15: ABARROTERIA AVILA | E15: 67347086 | G15: FUERA DE SERVICIO | H15: 46084 | I15: 0.57083333
A16: BOCAS DEL TORO | B16: Felix de leon | C16: ABARROTERIA JP STORE | E16: 67890276 | G16: NO CONTESTA | H16: 46084 | I16: 0.57152778
A17: BOCAS DEL TORO | B17: Felix de leon | C17: ABARROTERIA DON FRANCO | E17: 69463180 | G17: ASISTIRA | H17: 46084 | I17: 0.57361111
A18: BOCAS DEL TORO | B18: Felix de leon | C18: DOGGIES PELUQUERIA | E18: 68025745 | G18: NO CONTESTA | H18: 46084 | I18: 0.58333333
A19: BOCAS DEL TORO | B19: Felix de leon | C19: FRUTAS Y LEGUMBRES LA COMADRE | E19: 62706227 | G19: NO LLAMAR | H19: 46084 | I19: 0.58541667
A20: BOCAS DEL TORO | B20: Felix de leon | C20: SUNSET BEACH LOUNGE | E20: 60331992 | G20: ASISTIRA | H20: 46084 | I20: 0.58819444
A21: BOCAS DEL TORO | B21: Felix de leon | C21: LEGUMBRES Y VERDURAS EDUARDO | E21: 60581179 | G21: ASISTIRA | H21: 46084 | I21: 0.59166667
A22: BOCAS DEL TORO | B22: Felix de leon | C22: MINT MAKEUP& BEAUTY SALON | E22: 7871997 | G22: NO CONTESTA | H22: 46084 | I22: 0.59236111
A23: BOCAS DEL TORO | B23: Felix de leon | C23: FONDA EL ECONOMICO | E23: 62407921 | G23: APAGADO | H23: 46084 | I23: 0.59722222
A24: BOCAS DEL TORO | B24: Felix de leon | C24: FONDA MARISOL | E24: 63438357 | G24: NO CONTESTA | H24: 46084 | I24: 0.59791667
A25: BOCAS DEL TORO | B25: Felix de leon | C25: BARBERIA THE FAMILY | E25: 7214011 | G25: NO CONTESTA | H25: 46084 | I25: 0.59861111
A26: BOCAS DEL TORO | B26: Felix de leon | C26: ABARROTERIA LA VICTORIA | D26: venelda fossatti | E26: 63511676 | G26: ASISTIRA | H26: 46084 | I26: 0.60347222
A27: BOCAS DEL TORO | B27: Felix de leon | C27: ABARROTERIA HEIS-LIM | E27: 68317627 | G27: ASISTIRA | H27: 46084 | I27: 0.60694444
A28: BOCAS DEL TORO | B28: Felix de leon | C28: ABARROTERIA JOHANA | E28: 62240942 | G28: NO CONTESTA | H28: 46084 | I28: 0.60833333
A29: BOCAS DEL TORO | B29: Felix de leon | C29: ABARROTERIA LORENIRI | E29: 7756223 | G29: NO PODRA ASISTIR | H29: 46084 | I29: 0.61597222
A30: BOCAS DEL TORO | B30: Felix de leon | C30: ABARROTERIA HERMANOS LARA | E30: 65609160 | G30: FUERA DE SERVICIO | H30: 46084 | I30: 0.61666667
A31: BOCAS DEL TORO | B31: Felix de leon | C31: ABARROTERIA ELISBETH | E31: 67059161 | G31: APAGADO | H31: 46084 | I31: 0.62847222
A32: BOCAS DEL TORO | B32: Felix de leon | C32: ASADO EL PATRON | E32: 64365821 | G32: NO CONTESTA | H32: 46084 | I32: 0.62986111
A33: BOCAS DEL TORO | B33: Felix de leon | C33: REFRESQUERIA JOHANA | E33: 69357202 | G33: APAGADO | H33: 46084 | I33: 0.63611111
A34: BOCAS DEL TORO | B34: Felix de leon | C34: CAFE BOQUETE BY FOOD GRILL | E34: 6318643 | G34: FUERA DE SERVICIO | H34: 46084 | I34: 0.63611111
A35: BOCAS DEL TORO | B35: Felix de leon | C35: COMPRA Y VENTA DE LEGUMBRES B. Y P. | E35: 67146420 | G35: ASISTIRA | H35: 46084 | I35: 0.63819444
A36: BOCAS DEL TORO | B36: Felix de leon | C36: CENTRO DE BELLEZA VERONICA SALON | E36: 6436-9908 | G36: APAGADO | H36: 46084 | I36: 0.64097222
A37: BOCAS DEL TORO | B37: Felix de leon | C37: FONDA MAMI DIOSA | E37: 65702749 | G37: ASISTIRA | H37: 46084 | I37: 0.64375
A38: BOCAS DEL TORO | B38: Felix de leon | C38: FONDA ARGENTINA | E38: 64845515 | G38: APAGADO | H38: 46084 | I38: 0.64652778
A39: BOCAS DEL TORO | B39: Felix de leon | C39: LOCAL S/N BARBERIA | E39: 69380847 | G39: APAGADO | H39: 46084 | I39: 0.65277778
A40: BOCAS DEL TORO | B40: Felix de leon | C40: ABARROTERIA EL CHAVITO | E40: 64298968 | G40: ASISTIRA | H40: 46087 | I40: 0.36180556
...
